Workbook
Name Slicer_Diabetes_status: #N/A
Name Slicer_Weight_status: #N/A

Sheet Healthcare
A1: Customer ID | B1: First name | C1: BMI | D1: HBA1C | E1: Heart Issues | F1: Any transplants | G1: Cancer history | H1: Number of Major Surgeries | I1: Smoker | J1: Weight status | K1: Diabetes status | L1: Date of birth | M1: Charges | N1: Hospital tier | O1: City tier | P1: State ID | Q1: Age
A2: Id1 | B2: Kelly | C2: 47.41 | D2: 7.47 | E2: No | F2: No | G2: No | H2: 0 | I2: Yes | J2: Obesity | K2: Diabetes | L2: =VLOOKUP(A2,'Hospitalisation Details'!$A$1:$N$2344,5,FALSE) -> 25123 | M2: =VLOOKUP(A2,'Hospitalisation Details'!$A$1:$N$2344,8,FALSE) -> 63770.43 | N2: =VLOOKUP(A2,'Hospitalisation Details'!$A$1:$N$2344,12,FALSE) -> tier - 1 | O2: =VLOOKUP(A2,'Hospitalisation Details'!$A$1:$N$2344,13,FALSE) -> tier - 3 | P2: =VLOOKUP(A2,'Hospitalisation Details'!$A$1:$N$2344,14,FALSE) -> R1013 | Q2: =VLOOKUP(A2,'Hospitalisation Details'!$A$1:$N$2344,6,FALSE) -> 54
A3: Id2 | B3: Matthew D | C3: 30.36 | D3: 5.77 | E3: No | F3: No | G3: No | H3: 0 | I3: Yes | J3: Obesity | K3: Prediabetes | L3: =VLOOKUP(A3,'Hospitalisation Details'!$A$1:$N$2344,5,FALSE) -> 28284 | M3: =VLOOKUP(A3,'Hospitalisation Details'!$A$1:$N$2344,8,FALSE) -> 62592.87 | N3: =VLOOKUP(A3,'Hospitalisation Details'!$A$1:$N$2344,12,FALSE) -> tier - 2 | O3: =VLOOKUP(A3,'Hospitalisation Details'!$A$1:$N$2344,13,FALSE) -> tier - 3 | P3: =VLOOKUP(A3,'Hospitalisation Details'!$A$1:$N$2344,14,FALSE) -> R1013 | Q3: =VLOOKUP(A3,'Hospitalisation Details'!$A$1:$N$2344,6,FALSE) -> 46
A4: Id3 | B4: Phil | C4: 34.485 | D4: 11.87 | E4: Yes | F4: No | G4: No | H4: 2 | I4: Yes | J4: Obesity | K4: Diabetes | L4: =VLOOKUP(A4,'Hospitalisation Details'!$A$1:$N$2344,5,FALSE) -> 25822 | M4: =VLOOKUP(A4,'Hospitalisation Details'!$A$1:$N$2344,8,FALSE) -> 60021.4 | N4: =VLOOKUP(A4,'Hospitalisation Details'!$A$1:$N$2344,12,FALSE) -> tier - 1 | O4: =VLOOKUP(A4,'Hospitalisation Details'!$A$1:$N$2344,13,FALSE) -> tier - 1 | P4: =VLOOKUP(A4,'Hospitalisation Details'!$A$1:$N$2344,14,FALSE) -> R1012 | Q4: =VLOOKUP(A4,'Hospitalisation Details'!$A$1:$N$2344,6,FALSE) -> 52
A5: Id4 | B5: Kelsey | C5: 38.095 | D5: 6.05 | E5: No | F5: No | G5: No | H5: 0 | I5: Yes | J5: Obesity | K5: Prediabetes | L5: =VLOOKUP(A5,'Hospitalisation Details'!$A$1:$N$2344,5,FALSE) -> 33395 | M5: =VLOOKUP(A5,'Hospitalisation Details'!$A$1:$N$2344,8,FALSE) -> 58571.07 | N5: =VLOOKUP(A5,'Hospitalisation Details'!$A$1:$N$2344,12,FALSE) -> tier - 1 | O5: =VLOOKUP(A5,'Hospitalisation Details'!$A$1:$N$2344,13,FALSE) -> tier - 3 | P5: =VLOOKUP(A5,'Hospitalisation Details'!$A$1:$N$2344,14,FALSE) -> R1024 | Q5: =VLOOKUP(A5,'Hospitalisation Details'!$A$1:$N$2344,6,FALSE) -> 32
A6: Id5 | B6: Kristyn | C6: 35.53 | D6: 5.45 | E6: No | F6: No | G6: No | H6: 0 | I6: Yes | J6: Obesity | K6: Normal | L6: =VLOOKUP(A6,'Hospitalisation Details'!$A$1:$N$2344,5,FALSE) -> 32678 | M6: =VLOOKUP(A6,'Hospitalisation Details'!$A$1:$N$2344,8,FALSE) -> 55135.4 | N6: =VLOOKUP(A6,'Hospitalisation Details'!$A$1:$N$2344,12,FALSE) -> tier - 1 | O6: =VLOOKUP(A6,'Hospitalisation Details'!$A$1:$N$2344,13,FALSE) -> tier - 2 | P6: =VLOOKUP(A6,'Hospitalisation Details'!$A$1:$N$2344,14,FALSE) -> R1012 | Q6: =VLOOKUP(A6,'Hospitalisation Details'!$A$1:$N$2344,6,FALSE) -> 33
A7: Id6 | B7: Russell B | C7: 32.8 | D7: 6.59 | E7: No | F7: No | G7: No | H7: 0 | I7: Yes | J7: Obesity | K7: Diabetes | L7: =VLOOKUP(A7,'Hospitalisation Details'!$A$1:$N$2344,5,FALSE) -> 22862 | M7: =VLOOKUP(A7,'Hospitalisation Details'!$A$1:$N$2344,8,FALSE) -> 52590.83 | N7: =VLOOKUP(A7,'Hospitalisation Details'!$A$1:$N$2344,12,FALSE) -> tier - 1 | O7: =VLOOKUP(A7,'Hospitalisation Details'!$A$1:$N$2344,13,FALSE) -> tier - 3 | P7: =VLOOKUP(A7,'Hospitalisation Details'!$A$1:$N$2344,14,FALSE) -> R1011 | Q7: =VLOOKUP(A7,'Hospitalisation Details'!$A$1:$N$2344,6,FALSE) -> 60
A8: Id7 | B8: Scott | C8: 36.4 | D8: 6.07 | E8: No | F8: No | G8: No | H8: 0 | I8: Yes | J8: Obesity | K8: Prediabetes | L8: =VLOOKUP(A8,'Hospitalisation Details'!$A$1:$N$2344,5,FALSE) -> 34634 | M8: =VLOOKUP(A8,'Hospitalisation Details'!$A$1:$N$2344,8,FALSE) -> 51194.56 | N8: =VLOOKUP(A8,'Hospitalisation Details'!$A$1:$N$2344,12,FALSE) -> tier - 1 | O8: =VLOOKUP(A8,'Hospitalisation Details'!$A$1:$N$2344,13,FALSE) -> tier - 3 | P8: =VLOOKUP(A8,'Hospitalisation Details'!$A$1:$N$2344,14,FALSE) -> R1011 | Q8: =VLOOKUP(A8,'Hospitalisation Details'!$A$1:$N$2344,6,FALSE) -> 28
A9: Id8 | B9: Stephen | C9: 36.96 | D9: 7.93 | E9: No | F9: No | G9: No | H9: 3 | I9: Yes | J9: Obesity | K9: Diabetes | L9: =VLOOKUP(A9,'Hospitalisation Details'!$A$1:$N$2344,5,FALSE) -> 21363 | M9: =VLOOKUP(A9,'Hospitalisation Details'!$A$1:$N$2344,8,FALSE) -> 49577.66 | N9: =VLOOKUP(A9,'Hospitalisation Details'!$A$1:$N$2344,12,FALSE) -> tier - 2 | O9: =VLOOKUP(A9,'Hospitalisation Details'!$A$1:$N$2344,13,FALSE) -> tier - 2 | P9: =VLOOKUP(A9,'Hospitalisation Details'!$A$1:$N$2344,14,FALSE) -> R1013 | Q9: =VLOOKUP(A9,'Hospitalisation Details'!$A$1:$N$2344,6,FALSE) -> 64
A10: Id9 | B10: Patrick R | C10: 41.14 | D10: 9.58 | E10: Yes | F10: No | G10: Yes | H10: 1 | I10: Yes | J10: Obesity | K10: Diabetes | L10: =VLOOKUP(A10,'Hospitalisation Details'!$A$1:$N$2344,5,FALSE) -> 23258 | M10: =VLOOKUP(A10,'Hospitalisation Details'!$A$1:$N$2344,8,FALSE) -> 48970.25 | N10: =VLOOKUP(A10,'Hospitalisation Details'!$A$1:$N$2344,12,FALSE) -> tier - 1 | O10: =VLOOKUP(A10,'Hospitalisation Details'!$A$1:$N$2344,13,FALSE) -> tier - 2 | P10: =VLOOKUP(A10,'Hospitalisation Details'!$A$1:$N$2344,14,FALSE) -> R1013 | Q10: =VLOOKUP(A10,'Hospitalisation Details'!$A$1:$N$2344,6,FALSE) -> 59
A11: Id10 | B11: Brooke N | C11: 38.06 | D11: 10.79 | E11: No | F11: No | G11: No | H11: 0 | I11: Yes | J11: Obesity | K11: Diabetes | L11: =VLOOKUP(A11,'Hospitalisation Details'!$A$1:$N$2344,5,FALSE) -> 28853 | M11: =VLOOKUP(A11,'Hospitalisation Details'!$A$1:$N$2344,8,FALSE) -> 48885.14 | N11: =VLOOKUP(A11,'Hospitalisation Details'!$A$1:$N$2344,12,FALSE) -> tier - 1 | O11: =VLOOKUP(A11,'Hospitalisation Details'!$A$1:$N$2344,13,FALSE) -> tier - 2 | P11: =VLOOKUP(A11,'Hospitalisation Details'!$A$1:$N$2344,14,FALSE) -> R1013 | Q11: =VLOOKUP(A11,'Hospitalisation Details'!$A$1:$N$2344,6,FALSE) -> 44
A12: Id11 | B12: Paola Andrea | C12: 37.7 | D12: 5.96 | E12: Yes | F12: No | G12: No | H12: 2 | I12: Yes | J12: Obesity | K12: Prediabetes | L12: =VLOOKUP(A12,'Hospitalisation Details'!$A$1:$N$2344,5,FALSE) -> 21753 | M12: =VLOOKUP(A12,'Hospitalisation Details'!$A$1:$N$2344,8,FALSE) -> 48824.45 | N12: =VLOOKUP(A12,'Hospitalisation Details'!$A$1:$N$2344,12,FALSE) -> tier - 2 | O12: =VLOOKUP(A12,'Hospitalisation Details'!$A$1:$N$2344,13,FALSE) -> tier - 1 | P12: =VLOOKUP(A12,'Hospitalisation Details'!$A$1:$N$2344,14,FALSE) -> R1011 | Q12: =VLOOKUP(A12,'Hospitalisation Details'!$A$1:$N$2344,6,FALSE) -> 63
A13: Id12 | B13: David | C13: 42.13 | D13: 11.9 | E13: No | F13: No | G13: No | H13: 0 | I13: Yes | J13: Obesity | K13: Diabetes | L13: =VLOOKUP(A13,'Hospitalisation Details'!$A$1:$N$2344,5,FALSE) -> 24042 | M13: =VLOOKUP(A13,'Hospitalisation Details'!$A$1:$N$2344,8,FALSE) -> 48675.52 | N13: =VLOOKUP(A13,'Hospitalisation Details'!$A$1:$N$2344,12,FALSE) -> tier - 1 | O13: =VLOOKUP(A13,'Hospitalisation Details'!$A$1:$N$2344,13,FALSE) -> tier - 2 | P13: =VLOOKUP(A13,'Hospitalisation Details'!$A$1:$N$2344,14,FALSE) -> R1013 | Q13: =VLOOKUP(A13,'Hospitalisation Details'!$A$1:$N$2344,6,FALSE) -> 57
... A2336: Id2335 | B2336: Aaron K | C2336: 17.58 | D2336: 4.51 | E2336: No | F2336: No | G2336: No | H2336: 1 | I2336: No | J2336: Underweight | K2336: Normal | L2336: =VLOOKUP(A2336,'Hospitalisation Details'!$A$1:$N$2344,5,FALSE) -> 33794 | M2336: =VLOOKUP(A2336,'Hospitalisation Details'!$A$1:$N$2344,8,FALSE) -> 563.84 | N2336: =VLOOKUP(A2336,'Hospitalisation Details'!$A$1:$N$2344,12,FALSE) -> tier - 2 | O2336: =VLOOKUP(A2336,'Hospitalisation Details'!$A$1:$N$2344,13,FALSE) -> tier - 3 | P2336: =VLOOKUP(A2336,'Hospitalisation Details'!$A$1:$N$2344,14,FALSE) -> R1013 | Q2336: =VLOOKUP(A2336,'Hospitalisation Details'!$A$1:$N$2344,6,FALSE) -> 30
G2339: sum | H2339: =SUM(H2:H2336) -> 1579

Sheet Customer Names
A1: Customer ID | B1: name | C1: Last name | D1: Title | E1: First name
A2: Id1 | B2: Hawks, Ms. Kelly | C2: Hawks | D2: Ms | E2: Kelly
A3: Id2 | B3: Lehner, Mr. Matthew D | C3: Lehner | D3: Mr | E3: Matthew D
A4: Id3 | B4: Lu, Mr. Phil | C4: Lu | D4: Mr | E4: Phil
A5: Id4 | B5: Osborne, Ms. Kelsey | C5: Osborne | D5: Ms | E5: Kelsey
A6: Id5 | B6: Kadala, Ms. Kristyn | C6: Kadala | D6: Ms | E6: Kristyn
A7: Id6 | B7: Baker, Mr. Russell B. | C7: Baker | D7: Mr | E7: Russell B
A8: Id7 | B8: Macpherson, Mr. Scott | C8: Macpherson | D8: Mr | E8: Scott
A9: Id8 | B9: Hallman, Mr. Stephen | C9: Hallman | D9: Mr | E9: Stephen
A10: Id9 | B10: Moran, Mr. Patrick R. | C10: Moran | D10: Mr | E10: Patrick R
A11: Id10 | B11: Benner, Ms. Brooke N. | C11: Benner | D11: Ms | E11: Brooke N
A12: Id11 | B12: Fierro Vargas, Ms. Paola Andrea | C12: Fierro Vargas | D12: Ms | E12: Paola Andrea
... A2336: Id2335 | B2336: German, Mr. Aaron K | C2336: German | D2336: Mr | E2336: Aaron K

Sheet Medical Examinations
A1: Customer ID | B1: BMI | C1: HBA1C | D1: Heart Issues | E1: Any Transplants | F1: Cancer history | G1: NumberOfMajorSurgeries | H1: smoker | Q1: Number of Major Surgeries | R1: Heart Issues | T1: Smoker | U1: Weight status | V1: Diabetes status | W1: Any transplants
A2: Id1 | B2: 47.41 | C2: 7.47 | D2: No | E2: No | F2: No | G2: No major surgery | H2: yes | I2: =CLEAN(A2) -> Id1 | J2: =CLEAN(B2) -> 47.41 | K2: =CLEAN(C2) -> 7.47 | L2: =CLEAN(D2) -> No | M2: =CLEAN(E2) -> No | N2: =CLEAN(F2) -> No | O2: =CLEAN(G2) -> No major surgery | P2: =CLEAN(H2) -> yes | Q2: =SUBSTITUTE(O2,"No major surgery",0) -> 0 | R2: =PROPER(L2) -> No | S2: =PROPER(P2) -> Yes | T2: =SUBSTITUTE(S2,"?","No") -> Yes | U2: {=_xlfn.IFS(B2<18.5,"Underweight",B2<=24.9,"Normal weight",B2<=29.99,"Over weight",B2>=30,"Obesity")} -> Obesity | V2: {=_xlfn.IFS(C2<5.7,"Normal",C2<=6.49,"Prediabetes",C2>=6.5,"Diabetes")} -> Diabetes | W2: =PROPER(E2) -> No
A3: Id2 | B3: 30.36 | C3: 5.77 | D3: No | E3: No | F3: No | G3: No major surgery | H3: yes | I3: =CLEAN(A3) -> Id2 | J3: =CLEAN(B3) -> 30.36 | K3: =CLEAN(C3) -> 5.77 | L3: =CLEAN(D3) -> No | M3: =CLEAN(E3) -> No | N3: =CLEAN(F3) -> No | O3: =CLEAN(G3) -> No major surgery | P3: =CLEAN(H3) -> yes | Q3: =SUBSTITUTE(O3,"No major surgery",0) -> 0 | R3: =PROPER(L3) -> No | S3: =PROPER(P3) -> Yes | T3: =SUBSTITUTE(S3,"?","No") -> Yes | U3: {=_xlfn.IFS(B3<18.5,"Underweight",B3<=24.9,"Normal weight",B3<=29.99,"Over weight",B3>=30,"Obesity")} -> Obesity | V3: {=_xlfn.IFS(C3<5.7,"Normal",C3<=6.49,"Prediabetes",C3>=6.5,"Diabetes")} -> Prediabetes | W3: =PROPER(E3) -> No
A4: Id3 | B4: 34.485 | C4: 11.87 | D4: yes | E4: No | F4: No | G4: 2 | H4: yes | I4: =CLEAN(A4) -> Id3 | J4: =CLEAN(B4) -> 34.485 | K4: =CLEAN(C4) -> 11.87 | L4: =CLEAN(D4) -> yes | M4: =CLEAN(E4) -> No | N4: =CLEAN(F4) -> No | O4: =CLEAN(G4) -> 2 | P4: =CLEAN(H4) -> yes | Q4: =SUBSTITUTE(O4,"No major surgery",0) -> 2 | R4: =PROPER(L4) -> Yes | S4: =PROPER(P4) -> Yes | T4: =SUBSTITUTE(S4,"?","No") -> Yes | U4: {=_xlfn.IFS(B4<18.5,"Underweight",B4<=24.9,"Normal weight",B4<=29.99,"Over weight",B4>=30,"Obesity")} -> Obesity | V4: {=_xlfn.IFS(C4<5.7,"Normal",C4<=6.49,"Prediabetes",C4>=6.5,"Diabetes")} -> Diabetes | W4: =PROPER(E4) -> No
A5: Id4 | B5: 38.095 | C5: 6.05 | D5: No | E5: No | F5: No | G5: No major surgery | H5: yes | I5: =CLEAN(A5) -> Id4 | J5: =CLEAN(B5) -> 38.095 | K5: =CLEAN(C5) -> 6.05 | L5: =CLEAN(D5) -> No | M5: =CLEAN(E5) -> No | N5: =CLEAN(F5) -> No | O5: =CLEAN(G5) -> No major surgery | P5: =CLEAN(H5) -> yes | Q5: =SUBSTITUTE(O5,"No major surgery",0) -> 0 | R5: =PROPER(L5) -> No | S5: =PROPER(P5) -> Yes | T5: =SUBSTITUTE(S5,"?","No") -> Yes | U5: {=_xlfn.IFS(B5<18.5,"Underweight",B5<=24.9,"Normal weight",B5<=29.99,"Over weight",B5>=30,"Obesity")} -> Obesity | V5: {=_xlfn.IFS(C5<5.7,"Normal",C5<=6.49,"Prediabetes",C5>=6.5,"Diabetes")} -> Prediabetes | W5: =PROPER(E5) -> No
A6: Id5 | B6: 35.53 | C6: 5.45 | D6: No | E6: No | F6: No | G6: No major surgery | H6: yes | I6: =CLEAN(A6) -> Id5 | J6: =CLEAN(B6) -> 35.53 | K6: =CLEAN(C6) -> 5.45 | L6: =CLEAN(D6) -> No | M6: =CLEAN(E6) -> No | N6: =CLEAN(F6) -> No | O6: =CLEAN(G6) -> No major surgery | P6: =CLEAN(H6) -> yes | Q6: =SUBSTITUTE(O6,"No major surgery",0) -> 0 | R6: =PROPER(L6) -> No | S6: =PROPER(P6) -> Yes | T6: =SUBSTITUTE(S6,"?","No") -> Yes | U6: {=_xlfn.IFS(B6<18.5,"Underweight",B6<=24.9,"Normal weight",B6<=29.99,"Over weight",B6>=30,"Obesity")} -> Obesity | V6: {=_xlfn.IFS(C6<5.7,"Normal",C6<=6.49,"Prediabetes",C6>=6.5,"Diabetes")} -> Normal | W6: =PROPER(E6) -> No
A7: Id6 | B7: 32.8 | C7: 6.59 | D7: No | E7: No | F7: No | G7: No major surgery | H7: yes | I7: =CLEAN(A7) -> Id6 | J7: =CLEAN(B7) -> 32.8 | K7: =CLEAN(C7) -> 6.59 | L7: =CLEAN(D7) -> No | M7: =CLEAN(E7) -> No | N7: =CLEAN(F7) -> No | O7: =CLEAN(G7) -> No major surgery | P7: =CLEAN(H7) -> yes | Q7: =SUBSTITUTE(O7,"No major surgery",0) -> 0 | R7: =PROPER(L7) -> No | S7: =PROPER(P7) -> Yes | T7: =SUBSTITUTE(S7,"?","No") -> Yes | U7: {=_xlfn.IFS(B7<18.5,"Underweight",B7<=24.9,"Normal weight",B7<=29.99,"Over weight",B7>=30,"Obesity")} -> Obesity | V7: {=_xlfn.IFS(C7<5.7,"Normal",C7<=6.49,"Prediabetes",C7>=6.5,"Diabetes")} -> Diabetes | W7: =PROPER(E7) -> No
A8: Id7 | B8: 36.4 | C8: 6.07 | D8: No | E8: No | F8: No | G8: No major surgery | H8: yes | I8: =CLEAN(A8) -> Id7 | J8: =CLEAN(B8) -> 36.4 | K8: =CLEAN(C8) -> 6.07 | L8: =CLEAN(D8) -> No | M8: =CLEAN(E8) -> No | N8: =CLEAN(F8) -> No | O8: =CLEAN(G8) -> No major surgery | P8: =CLEAN(H8) -> yes | Q8: =SUBSTITUTE(O8,"No major surgery",0) -> 0 | R8: =PROPER(L8) -> No | S8: =PROPER(P8) -> Yes | T8: =SUBSTITUTE(S8,"?","No") -> Yes | U8: {=_xlfn.IFS(B8<18.5,"Underweight",B8<=24.9,"Normal weight",B8<=29.99,"Over weight",B8>=30,"Obesity")} -> Obesity | V8: {=_xlfn.IFS(C8<5.7,"Normal",C8<=6.49,"Prediabetes",C8>=6.5,"Diabetes")} -> Prediabetes | W8: =PROPER(E8) -> No
A9: Id8 | B9: 36.96 | C9: 7.93 | D9: No | E9: No | F9: No | G9: 3 | H9: yes | I9: =CLEAN(A9) -> Id8 | J9: =CLEAN(B9) -> 36.96 | K9: =CLEAN(C9) -> 7.93 | L9: =CLEAN(D9) -> No | M9: =CLEAN(E9) -> No | N9: =CLEAN(F9) -> No | O9: =CLEAN(G9) -> 3 | P9: =CLEAN(H9) -> yes | Q9: =SUBSTITUTE(O9,"No major surgery",0) -> 3 | R9: =PROPER(L9) -> No | S9: =PROPER(P9) -> Yes | T9: =SUBSTITUTE(S9,"?","No") -> Yes | U9: {=_xlfn.IFS(B9<18.5,"Underweight",B9<=24.9,"Normal weight",B9<=29.99,"Over weight",B9>=30,"Obesity")} -> Obesity | V9: {=_xlfn.IFS(C9<5.7,"Normal",C9<=6.49,"Prediabetes",C9>=6.5,"Diabetes")} -> Diabetes | W9: =PROPER(E9) -> No
A10: Id9 | B10: 41.14 | C10: 9.58 | D10: yes | E10: No | F10: Yes | G10: 1 | H10: yes | I10: =CLEAN(A10) -> Id9 | J10: =CLEAN(B10) -> 41.14 | K10: =CLEAN(C10) -> 9.58 | L10: =CLEAN(D10) -> yes | M10: =CLEAN(E10) -> No | N10: =CLEAN(F10) -> Yes | O10: =CLEAN(G10) -> 1 | P10: =CLEAN(H10) -> yes | Q10: =SUBSTITUTE(O10,"No major surgery",0) -> 1 | R10: =PROPER(L10) -> Yes | S10: =PROPER(P10) -> Yes | T10: =SUBSTITUTE(S10,"?","No") -> Yes | U10: {=_xlfn.IFS(B10<18.5,"Underweight",B10<=24.9,"Normal weight",B10<=29.99,"Over weight",B10>=30,"Obesity")} -> Obesity | V10: {=_xlfn.IFS(C10<5.7,"Normal",C10<=6.49,"Prediabetes",C10>=6.5,"Diabetes")} -> Diabetes | W10: =PROPER(E10) -> No
A11: Id10 | B11: 38.06 | C11: 10.79 | D11: No | E11: No | F11: No | G11: No major surgery | H11: yes | I11: =CLEAN(A11) -> Id10 | J11: =CLEAN(B11) -> 38.06 | K11: =CLEAN(C11) -> 10.79 | L11: =CLEAN(D11) -> No | M11: =CLEAN(E11) -> No | N11: =CLEAN(F11) -> No | O11: =CLEAN(G11) -> No major surgery | P11: =CLEAN(H11) -> yes | Q11: =SUBSTITUTE(O11,"No major surgery",0) -> 0 | R11: =PROPER(L11) -> No | S11: =PROPER(P11) -> Yes | T11: =SUBSTITUTE(S11,"?","No") -> Yes | U11: {=_xlfn.IFS(B11<18.5,"Underweight",B11<=24.9,"Normal weight",B11<=29.99,"Over weight",B11>=30,"Obesity")} -> Obesity | V11: {=_xlfn.IFS(C11<5.7,"Normal",C11<=6.49,"Prediabetes",C11>=6.5,"Diabetes")} -> Diabetes | W11: =PROPER(E11) -> No
A12: Id11 | B12: 37.7 | C12: 5.96 | D12: yes | E12: No | F12: No | G12: 2 | H12: yes | I12: =CLEAN(A12) -> Id11 | J12: =CLEAN(B12) -> 37.7 | K12: =CLEAN(C12) -> 5.96 | L12: =CLEAN(D12) -> yes | M12: =CLEAN(E12) -> No | N12: =CLEAN(F12) -> No | O12: =CLEAN(G12) -> 2 | P12: =CLEAN(H12) -> yes | Q12: =SUBSTITUTE(O12,"No major surgery",0) -> 2 | R12: =PROPER(L12) -> Yes | S12: =PROPER(P12) -> Yes | T12: =SUBSTITUTE(S12,"?","No") -> Yes | U12: {=_xlfn.IFS(B12<18.5,"Underweight",B12<=24.9,"Normal weight",B12<=29.99,"Over weight",B12>=30,"Obesity")} -> Obesity | V12: {=_xlfn.IFS(C12<5.7,"Normal",C12<=6.49,"Prediabetes",C12>=6.5,"Diabetes")} -> Prediabetes | W12: =PROPER(E12) -> No
A13: Id12 | B13: 42.13 | C13: 11.9 | D13: No | E13: No | F13: No | G13: No major surgery | H13: yes | I13: =CLEAN(A13) -> Id12 | J13: =CLEAN(B13) -> 42.13 | K13: =CLEAN(C13) -> 11.9 | L13: =CLEAN(D13) -> No | M13: =CLEAN(E13) -> No | N13: =CLEAN(F13) -> No | O13: =CLEAN(G13) -> No major surgery | P13: =CLEAN(H13) -> yes | Q13: =SUBSTITUTE(O13,"No major surgery",0) -> 0 | R13: =PROPER(L13) -> No | S13: =PROPER(P13) -> Yes | T13: =SUBSTITUTE(S13,"?","No") -> Yes | U13: {=_xlfn.IFS(B13<18.5,"Underweight",B13<=24.9,"Normal weight",B13<=29.99,"Over weight",B13>=30,"Obesity")} -> Obesity | V13: {=_xlfn.IFS(C13<5.7,"Normal",C13<=6.49,"Prediabetes",C13>=6.5,"Diabetes")} -> Diabetes | W13: =PROPER(E13) -> No
A14: Id13 | B14: 40.92 | C14: 8.41 | D14: No | E14: No | F14: No | G14: No major surgery | H14: yes | I14: =CLEAN(A14) -> Id13 | J14: =CLEAN(B14) -> 40.92 | K14: =CLEAN(C14) -> 8.41 | L14: =CLEAN(D14) -> No | M14: =CLEAN(E14) -> No | N14: =CLEAN(F14) -> No | O14: =CLEAN(G14) -> No major surgery | P14: =CLEAN(H14) -> yes | Q14: =SUBSTITUTE(O14,"No major surgery",0) -> 0 | R14: =PROPER(L14) -> No | S14: =PROPER(P14) -> Yes | T14: =SUBSTITUTE(S14,"?","No") -> Yes | U14: {=_xlfn.IFS(B14<18.5,"Underweight",B14<=24.9,"Normal weight",B14<=29.99,"Over weight",B14>=30,"Obesity")} -> Obesity | V14: {=_xlfn.IFS(C14<5.7,"Normal",C14<=6.49,"Prediabetes",C14>=6.5,"Diabetes")} -> Diabetes | W14: =PROPER(E14) -> No
A15: Id14 | B15: 40.565 | C15: 7.02 | D15: No | E15: No | F15: No | G15: No major surgery | H15: yes | I15: =CLEAN(A15) -> Id14 | J15: =CLEAN(B15) -> 40.565 | K15: =CLEAN(C15) -> 7.02 | L15: =CLEAN(D15) -> No | M15: =CLEAN(E15) -> No | N15: =CLEAN(F15) -> No | O15: =CLEAN(G15) -> No major surgery | P15: =CLEAN(H15) -> yes | Q15: =SUBSTITUTE(O15,"No major surgery",0) -> 0 | R15: =PROPER(L15) -> No | S15: =PROPER(P15) -> Yes | T15: =SUBSTITUTE(S15,"?","No") -> Yes | U15: {=_xlfn.IFS(B15<18.5,"Underweight",B15<=24.9,"Normal weight",B15<=29.99,"Over weight",B15>=30,"Obesity")} -> Obesity | V15: {=_xlfn.IFS(C15<5.7,"Normal",C15<=6.49,"Prediabetes",C15>=6.5,"Diabetes")} -> Diabetes | W15: =PROPER(E15) -> No
A16: Id15 | B16: 36.385 | C16: 7.59 | D16: yes | E16: No | F16: No | G16: 2 | H16: yes | I16: =CLEAN(A16) -> Id15 | J16: =CLEAN(B16) -> 36.385 | K16: =CLEAN(C16) -> 7.59 | L16: =CLEAN(D16) -> yes | M16: =CLEAN(E16) -> No | N16: =CLEAN(F16) -> No | O16: =CLEAN(G16) -> 2 | P16: =CLEAN(H16) -> yes | Q16: =SUBSTITUTE(O16,"No major surgery",0) -> 2 | R16: =PROPER(L16) -> Yes | S16: =PROPER(P16) -> Yes | T16: =SUBSTITUTE(S16,"?","No") -> Yes | U16: {=_xlfn.IFS(B16<18.5,"Underweight",B16<=24.9,"Normal weight",B16<=29.99,"Over weight",B16>=30,"Obesity")} -> Obesity | V16: {=_xlfn.IFS(C16<5.7,"Normal",C16<=6.49,"Prediabetes",C16>=6.5,"Diabetes")} -> Diabetes | W16: =PROPER(E16) -> No
A17: Id16 | B17: 39.9 | C17: 11.32 | D17: No | E17: No | F17: No | G17: No major surgery | H17: yes | I17: =CLEAN(A17) -> Id16 | J17: =CLEAN(B17) -> 39.9 | K17: =CLEAN(C17) -> 11.32 | L17: =CLEAN(D17) -> No | M17: =CLEAN(E17) -> No | N17: =CLEAN(F17) -> No | O17: =CLEAN(G17) -> No major surgery | P17: =CLEAN(H17) -> yes | Q17: =SUBSTITUTE(O17,"No major surgery",0) -> 0 | R17: =PROPER(L17) -> No | S17: =PROPER(P17) -> Yes | T17: =SUBSTITUTE(S17,"?","No") -> Yes | U17: {=_xlfn.IFS(B17<18.5,"Underweight",B17<=24.9,"Normal weight",B17<=29.99,"Over weight",B17>=30,"Obesity")} -> Obesity | V17: {=_xlfn.IFS(C17<5.7,"Normal",C17<=6.49,"Prediabetes",C17>=6.5,"Diabetes")} -> Diabetes | W17: =PROPER(E17) -> No
A18: Id17 | B18: 33.8 | C18: 7.67 | D18: No | E18: No | F18: No | G18: 3 | H18: yes | I18: =CLEAN(A18) -> Id17 | J18: =CLEAN(B18) -> 33.8 | K18: =CLEAN(C18) -> 7.67 | L18: =CLEAN(D18) -> No | M18: =CLEAN(E18) -> No | N18: =CLEAN(F18) -> No | O18: =CLEAN(G18) -> 3 | P18: =CLEAN(H18) -> yes | Q18: =SUBSTITUTE(O18,"No major surgery",0) -> 3 | R18: =PROPER(L18) -> No | S18: =PROPER(P18) -> Yes | T18: =SUBSTITUTE(S18,"?","No") -> Yes | U18: {=_xlfn.IFS(B18<18.5,"Underweight",B18<=24.9,"Normal weight",B18<=29.99,"Over weight",B18>=30,"Obesity")} -> Obesity | V18: {=_xlfn.IFS(C18<5.7,"Normal",C18<=6.49,"Prediabetes",C18>=6.5,"Diabetes")} -> Diabetes | W18: =PROPER(E18) -> No
A19: Id18 | B19: 36.765 | C19: 7.29 | D19: yes | E19: No | F19: Yes | G19: 1 | H19: yes | I19: =CLEAN(A19) -> Id18 | J19: =CLEAN(B19) -> 36.765 | K19: =CLEAN(C19) -> 7.29 | L19: =CLEAN(D19) -> yes | M19: =CLEAN(E19) -> No | N19: =CLEAN(F19) -> Yes | O19: =CLEAN(G19) -> 1 | P19: =CLEAN(H19) -> yes | Q19: =SUBSTITUTE(O19,"No major surgery",0) -> 1 | R19: =PROPER(L19) -> Yes | S19: =PROPER(P19) -> Yes | T19: =SUBSTITUTE(S19,"?","No") -> Yes | U19: {=_xlfn.IFS(B19<18.5,"Underweight",B19<=24.9,"Normal weight",B19<=29.99,"Over weight",B19>=30,"Obesity")} -> Obesity | V19: {=_xlfn.IFS(C19<5.7,"Normal",C19<=6.49,"Prediabetes",C19>=6.5,"Diabetes")} -> Diabetes | W19: =PROPER(E19) -> No
A20: Id19 | B20: 36.955 | C20: 4.72 | D20: yes | E20: No | F20: No | G20: 1 | H20: yes | I20: =CLEAN(A20) -> Id19 | J20: =CLEAN(B20) -> 36.955 | K20: =CLEAN(C20) -> 4.72 | L20: =CLEAN(D20) -> yes | M20: =CLEAN(E20) -> No | N20: =CLEAN(F20) -> No | O20: =CLEAN(G20) -> 1 | P20: =CLEAN(H20) -> yes | Q20: =SUBSTITUTE(O20,"No major surgery",0) -> 1 | R20: =PROPER(L20) -> Yes | S20: =PROPER(P20) -> Yes | T20: =SUBSTITUTE(S20,"?","No") -> Yes | U20: {=_xlfn.IFS(B20<18.5,"Underweight",B20<=24.9,"Normal weight",B20<=29.99,"Over weight",B20>=30,"Obesity")} -> Obesity | V20: {=_xlfn.IFS(C20<5.7,"Normal",C20<=6.49,"Prediabetes",C20>=6.5,"Diabetes")} -> Normal | W20: =PROPER(E20) -> No
A21: Id20 | B21: 42.9 | C21: 11.41 | D21: No | E21: No | F21: No | G21: No major surgery | H21: yes | I21: =CLEAN(A21) -> Id20 | J21: =CLEAN(B21) -> 42.9 | K21: =CLEAN(C21) -> 11.41 | L21: =CLEAN(D21) -> No | M21: =CLEAN(E21) -> No | N21: =CLEAN(F21) -> No | O21: =CLEAN(G21) -> No major surgery | P21: =CLEAN(H21) -> yes | Q21: =SUBSTITUTE(O21,"No major surgery",0) -> 0 | R21: =PROPER(L21) -> No | S21: =PROPER(P21) -> Yes | T21: =SUBSTITUTE(S21,"?","No") -> Yes | U21: {=_xlfn.IFS(B21<18.5,"Underweight",B21<=24.9,"Normal weight",B21<=29.99,"Over weight",B21>=30,"Obesity")} -> Obesity | V21: {=_xlfn.IFS(C21<5.7,"Normal",C21<=6.49,"Prediabetes",C21>=6.5,"Diabetes")} -> Diabetes | W21: =PROPER(E21) -> No
A22: Id21 | B22: 36.3 | C22: 11.5 | D22: yes | E22: No | F22: No | G22: 2 | H22: yes | I22: =CLEAN(A22) -> Id21 | J22: =CLEAN(B22) -> 36.3 | K22: =CLEAN(C22) -> 11.5 | L22: =CLEAN(D22) -> yes | M22: =CLEAN(E22) -> No | N22: =CLEAN(F22) -> No | O22: =CLEAN(G22) -> 2 | P22: =CLEAN(H22) -> yes | Q22: =SUBSTITUTE(O22,"No major surgery",0) -> 2 | R22: =PROPER(L22) -> Yes | S22: =PROPER(P22) -> Yes | T22: =SUBSTITUTE(S22,"?","No") -> Yes | U22: {=_xlfn.IFS(B22<18.5,"Underweight",B22<=24.9,"Normal weight",B22<=29.99,"Over weight",B22>=30,"Obesity")} -> Obesity | V22: {=_xlfn.IFS(C22<5.7,"Normal",C22<=6.49,"Prediabetes",C22>=6.5,"Diabetes")} -> Diabetes | W22: =PROPER(E22) -> No
A23: Id22 | B23: 32.2 | C23: 6.22 | D23: yes | E23: No | F23: No | G23: 2 | H23: yes | I23: =CLEAN(A23) -> Id22 | J23: =CLEAN(B23) -> 32.2 | K23: =CLEAN(C23) -> 6.22 | L23: =CLEAN(D23) -> yes | M23: =CLEAN(E23) -> No | N23: =CLEAN(F23) -> No | O23: =CLEAN(G23) -> 2 | P23: =CLEAN(H23) -> yes | Q23: =SUBSTITUTE(O23,"No major surgery",0) -> 2 | R23: =PROPER(L23) -> Yes | S23: =PROPER(P23) -> Yes | T23: =SUBSTITUTE(S23,"?","No") -> Yes | U23: {=_xlfn.IFS(B23<18.5,"Underweight",B23<=24.9,"Normal weight",B23<=29.99,"Over weight",B23>=30,"Obesity")} -> Obesity | V23: {=_xlfn.IFS(C23<5.7,"Normal",C23<=6.49,"Prediabetes",C23>=6.5,"Diabetes")} -> Prediabetes | W23: =PROPER(E23) -> No
A24: Id23 | B24: 31.3 | C24: 11.38 | D24: No | E24: No | F24: No | G24: 3 | H24: yes | I24: =CLEAN(A24) -> Id23 | J24: =CLEAN(B24) -> 31.3 | K24: =CLEAN(C24) -> 11.38 | L24: =CLEAN(D24) -> No | M24: =CLEAN(E24) -> No | N24: =CLEAN(F24) -> No | O24: =CLEAN(G24) -> 3 | P24: =CLEAN(H24) -> yes | Q24: =SUBSTITUTE(O24,"No major surgery",0) -> 3 | R24: =PROPER(L24) -> No | S24: =PROPER(P24) -> Yes | T24: =SUBSTITUTE(S24,"?","No") -> Yes | U24: {=_xlfn.IFS(B24<18.5,"Underweight",B24<=24.9,"Normal weight",B24<=29.99,"Over weight",B24>=30,"Obesity")} -> Obesity | V24: {=_xlfn.IFS(C24<5.7,"Normal",C24<=6.49,"Prediabetes",C24>=6.5,"Diabetes")} -> Diabetes | W24: =PROPER(E24) -> No
A25: Id24 | B25: 41.8 | C25: 7.89 | D25: yes | E25: No | F25: No | G25: 2 | H25: yes | I25: =CLEAN(A25) -> Id24 | J25: =CLEAN(B25) -> 41.8 | K25: =CLEAN(C25) -> 7.89 | L25: =CLEAN(D25) -> yes | M25: =CLEAN(E25) -> No | N25: =CLEAN(F25) -> No | O25: =CLEAN(G25) -> 2 | P25: =CLEAN(H25) -> yes | Q25: =SUBSTITUTE(O25,"No major surgery",0) -> 2 | R25: =PROPER(L25) -> Yes | S25: =PROPER(P25) -> Yes | T25: =SUBSTITUTE(S25,"?","No") -> Yes | U25: {=_xlfn.IFS(B25<18.5,"Underweight",B25<=24.9,"Normal weight",B25<=29.99,"Over weight",B25>=30,"Obesity")} -> Obesity | V25: {=_xlfn.IFS(C25<5.7,"Normal",C25<=6.49,"Prediabetes",C25>=6.5,"Diabetes")} -> Diabetes | W25: =PROPER(E25) -> No
A26: Id25 | B26: 35.09 | C26: 4.38 | D26: yes | E26: No | F26: No | G26: 2 | H26: yes | I26: =CLEAN(A26) -> Id25 | J26: =CLEAN(B26) -> 35.09 | K26: =CLEAN(C26) -> 4.38 | L26: =CLEAN(D26) -> yes | M26: =CLEAN(E26) -> No | N26: =CLEAN(F26) -> No | O26: =CLEAN(G26) -> 2 | P26: =CLEAN(H26) -> yes | Q26: =SUBSTITUTE(O26,"No major surgery",0) -> 2 | R26: =PROPER(L26) -> Yes | S26: =PROPER(P26) -> Yes | T26: =SUBSTITUTE(S26,"?","No") -> Yes | U26: {=_xlfn.IFS(B26<18.5,"Underweight",B26<=24.9,"Normal weight",B26<=29.99,"Over weight",B26>=30,"Obesity")} -> Obesity | V26: {=_xlfn.IFS(C26<5.7,"Normal",C26<=6.49,"Prediabetes",C26>=6.5,"Diabetes")} -> Normal | W26: =PROPER(E26) -> No
A27: Id26 | B27: 33.88 | C27: 7.01 | D27: No | E27: No | F27: No | G27: 3 | H27: yes | I27: =CLEAN(A27) -> Id26 | J27: =CLEAN(B27) -> 33.88 | K27: =CLEAN(C27) -> 7.01 | L27: =CLEAN(D27) -> No | M27: =CLEAN(E27) -> No | N27: =CLEAN(F27) -> No | O27: =CLEAN(G27) -> 3 | P27: =CLEAN(H27) -> yes | Q27: =SUBSTITUTE(O27,"No major surgery",0) -> 3 | R27: =PROPER(L27) -> No | S27: =PROPER(P27) -> Yes | T27: =SUBSTITUTE(S27,"?","No") -> Yes | U27: {=_xlfn.IFS(B27<18.5,"Underweight",B27<=24.9,"Normal weight",B27<=29.99,"Over weight",B27>=30,"Obesity")} -> Obesity | V27: {=_xlfn.IFS(C27<5.7,"Normal",C27<=6.49,"Prediabetes",C27>=6.5,"Diabetes")} -> Diabetes | W27: =PROPER(E27) -> No
A28: Id27 | B28: 30.875 | C28: 11.88 | D28: No | E28: No | F28: No | G28: No major surgery | H28: yes | I28: =CLEAN(A28) -> Id27 | J28: =CLEAN(B28) -> 30.875 | K28: =CLEAN(C28) -> 11.88 | L28: =CLEAN(D28) -> No | M28: =CLEAN(E28) -> No | N28: =CLEAN(F28) -> No | O28: =CLEAN(G28) -> No major surgery | P28: =CLEAN(H28) -> yes | Q28: =SUBSTITUTE(O28,"No major surgery",0) -> 0 | R28: =PROPER(L28) -> No | S28: =PROPER(P28) -> Yes | T28: =SUBSTITUTE(S28,"?","No") -> Yes | U28: {=_xlfn.IFS(B28<18.5,"Underweight",B28<=24.9,"Normal weight",B28<=29.99,"Over weight",B28>=30,"Obesity")} -> Obesity | V28: {=_xlfn.IFS(C28<5.7,"Normal",C28<=6.49,"Prediabetes",C28>=6.5,"Diabetes")} -> Diabetes | W28: =PROPER(E28) -> No
A29: Id28 | B29: 36.86 | C29: 5.19 | D29: yes | E29: No | F29: Yes | G29: 1 | H29: yes | I29: =CLEAN(A29) -> Id28 | J29: =CLEAN(B29) -> 36.86 | K29: =CLEAN(C29) -> 5.19 | L29: =CLEAN(D29) -> yes | M29: =CLEAN(E29) -> No | N29: =CLEAN(F29) -> Yes | O29: =CLEAN(G29) -> 1 | P29: =CLEAN(H29) -> yes | Q29: =SUBSTITUTE(O29,"No major surgery",0) -> 1 | R29: =PROPER(L29) -> Yes | S29: =PROPER(P29) -> Yes | T29: =SUBSTITUTE(S29,"?","No") -> Yes | U29: {=_xlfn.IFS(B29<18.5,"Underweight",B29<=24.9,"Normal weight",B29<=29.99,"Over weight",B29>=30,"Obesity")} -> Obesity | V29: {=_xlfn.IFS(C29<5.7,"Normal",C29<=6.49,"Prediabetes",C29>=6.5,"Diabetes")} -> Normal | W29: =PROPER(E29) -> No
A30: Id29 | B30: 35.86 | C30: 6.74 | D30: yes | E30: No | F30: No | G30: 2 | H30: yes | I30: =CLEAN(A30) -> Id29 | J30: =CLEAN(B30) -> 35.86 | K30: =CLEAN(C30) -> 6.74 | L30: =CLEAN(D30) -> yes | M30: =CLEAN(E30) -> No | N30: =CLEAN(F30) -> No | O30: =CLEAN(G30) -> 2 | P30: =CLEAN(H30) -> yes | Q30: =SUBSTITUTE(O30,"No major surgery",0) -> 2 | R30: =PROPER(L30) -> Yes | S30: =PROPER(P30) -> Yes | T30: =SUBSTITUTE(S30,"?","No") -> Yes | U30: {=_xlfn.IFS(B30<18.5,"Underweight",B30<=24.9,"Normal weight",B30<=29.99,"Over weight",B30>=30,"Obesity")} -> Obesity | V30: {=_xlfn.IFS(C30<5.7,"Normal",C30<=6.49,"Prediabetes",C30>=6.5,"Diabetes")} -> Diabetes | W30: =PROPER(E30) -> No
A31: Id30 | B31: 37.05 | C31: 8.44 | D31: No | E31: No | F31: No | G31: No major surgery | H31: yes | I31: =CLEAN(A31) -> Id30 | J31: =CLEAN(B31) -> 37.05 | K31: =CLEAN(C31) -> 8.44 | L31: =CLEAN(D31) -> No | M31: =CLEAN(E31) -> No | N31: =CLEAN(F31) -> No | O31: =CLEAN(G31) -> No major surgery | P31: =CLEAN(H31) -> yes | Q31: =SUBSTITUTE(O31,"No major surgery",0) -> 0 | R31: =PROPER(L31) -> No | S31: =PROPER(P31) -> Yes | T31: =SUBSTITUTE(S31,"?","No") -> Yes | U31: {=_xlfn.IFS(B31<18.5,"Underweight",B31<=24.9,"Normal weight",B31<=29.99,"Over weight",B31>=30,"Obesity")} -> Obesity | V31: {=_xlfn.IFS(C31<5.7,"Normal",C31<=6.49,"Prediabetes",C31>=6.5,"Diabetes")} -> Diabetes | W31: =PROPER(E31) -> No
A32: Id31 | B32: 43.89 | C32: 8.71 | D32: No | E32: No | F32: No | G32: No major surgery | H32: yes | I32: =CLEAN(A32) -> Id31 | J32: =CLEAN(B32) -> 43.89 | K32: =CLEAN(C32) -> 8.71 | L32: =CLEAN(D32) -> No | M32: =CLEAN(E32) -> No | N32: =CLEAN(F32) -> No | O32: =CLEAN(G32) -> No major surgery | P32: =CLEAN(H32) -> yes | Q32: =SUBSTITUTE(O32,"No major surgery",0) -> 0 | R32: =PROPER(L32) -> No | S32: =PROPER(P32) -> Yes | T32: =SUBSTITUTE(S32,"?","No") -> Yes | U32: {=_xlfn.IFS(B32<18.5,"Underweight",B32<=24.9,"Normal weight",B32<=29.99,"Over weight",B32>=30,"Obesity")} -> Obesity | V32: {=_xlfn.IFS(C32<5.7,"Normal",C32<=6.49,"Prediabetes",C32>=6.5,"Diabetes")} -> Diabetes | W32: =PROPER(E32) -> No
A33: Id32 | B33: 42.35 | C33: 5.08 | D33: yes | E33: No | F33: No | G33: No major surgery | H33: yes | I33: =CLEAN(A33) -> Id32 | J33: =CLEAN(B33) -> 42.35 | K33: =CLEAN(C33) -> 5.08 | L33: =CLEAN(D33) -> yes | M33: =CLEAN(E33) -> No | N33: =CLEAN(F33) -> No | O33: =CLEAN(G33) -> No major surgery | P33: =CLEAN(H33) -> yes | Q33: =SUBSTITUTE(O33,"No major surgery",0) -> 0 | R33: =PROPER(L33) -> Yes | S33: =PROPER(P33) -> Yes | T33: =SUBSTITUTE(S33,"?","No") -> Yes | U33: {=_xlfn.IFS(B33<18.5,"Underweight",B33<=24.9,"Normal weight",B33<=29.99,"Over weight",B33>=30,"Obesity")} -> Obesity | V33: {=_xlfn.IFS(C33<5.7,"Normal",C33<=6.49,"Prediabetes",C33>=6.5,"Diabetes")} -> Normal | W33: =PROPER(E33) -> No
A34: Id33 | B34: 31.35 | C34: 6.86 | D34: No | E34: No | F34: No | G34: No major surgery | H34: yes | I34: =CLEAN(A34) -> Id33 | J34: =CLEAN(B34) -> 31.35 | K34: =CLEAN(C34) -> 6.86 | L34: =CLEAN(D34) -> No | M34: =CLEAN(E34) -> No | N34: =CLEAN(F34) -> No | O34: =CLEAN(G34) -> No major surgery | P34: =CLEAN(H34) -> yes | Q34: =SUBSTITUTE(O34,"No major surgery",0) -> 0 | R34: =PROPER(L34) -> No | S34: =PROPER(P34) -> Yes | T34: =SUBSTITUTE(S34,"?","No") -> Yes | U34: {=_xlfn.IFS(B34<18.5,"Underweight",B34<=24.9,"Normal weight",B34<=29.99,"Over weight",B34>=30,"Obesity")} -> Obesity | V34: {=_xlfn.IFS(C34<5.7,"Normal",C34<=6.49,"Prediabetes",C34>=6.5,"Diabetes")} -> Diabetes | W34: =PROPER(E34) -> No
A35: Id34 | B35: 47.6 | C35: 5.95 | D35: yes | E35: No | F35: No | G35: No major surgery | H35: yes | I35: =CLEAN(A35) -> Id34 | J35: =CLEAN(B35) -> 47.6 | K35: =CLEAN(C35) -> 5.95 | L35: =CLEAN(D35) -> yes | M35: =CLEAN(E35) -> No | N35: =CLEAN(F35) -> No | O35: =CLEAN(G35) -> No major surgery | P35: =CLEAN(H35) -> yes | Q35: =SUBSTITUTE(O35,"No major surgery",0) -> 0 | R35: =PROPER(L35) -> Yes | S35: =PROPER(P35) -> Yes | T35: =SUBSTITUTE(S35,"?","No") -> Yes | U35: {=_xlfn.IFS(B35<18.5,"Underweight",B35<=24.9,"Normal weight",B35<=29.99,"Over weight",B35>=30,"Obesity")} -> Obesity | V35: {=_xlfn.IFS(C35<5.7,"Normal",C35<=6.49,"Prediabetes",C35>=6.5,"Diabetes")} -> Prediabetes | W35: =PROPER(E35) -> No
A36: Id35 | B36: 46.2 | C36: 6.09 | D36: No | E36: No | F36: Yes | G36: 1 | H36: yes | I36: =CLEAN(A36) -> Id35 | J36: =CLEAN(B36) -> 46.2 | K36: =CLEAN(C36) -> 6.09 | L36: =CLEAN(D36) -> No | M36: =CLEAN(E36) -> No | N36: =CLEAN(F36) -> Yes | O36: =CLEAN(G36) -> 1 | P36: =CLEAN(H36) -> yes | Q36: =SUBSTITUTE(O36,"No major surgery",0) -> 1 | R36: =PROPER(L36) -> No | S36: =PROPER(P36) -> Yes | T36: =SUBSTITUTE(S36,"?","No") -> Yes | U36: {=_xlfn.IFS(B36<18.5,"Underweight",B36<=24.9,"Normal weight",B36<=29.99,"Over weight",B36>=30,"Obesity")} -> Obesity | V36: {=_xlfn.IFS(C36<5.7,"Normal",C36<=6.49,"Prediabetes",C36>=6.5,"Diabetes")} -> Prediabetes | W36: =PROPER(E36) -> No
A37: Id36 | B37: 32.015 | C37: 11.75 | D37: No | E37: No | F37: No | G37: No major surgery | H37: yes | I37: =CLEAN(A37) -> Id36 | J37: =CLEAN(B37) -> 32.015 | K37: =CLEAN(C37) -> 11.75 | L37: =CLEAN(D37) -> No | M37: =CLEAN(E37) -> No | N37: =CLEAN(F37) -> No | O37: =CLEAN(G37) -> No major surgery | P37: =CLEAN(H37) -> yes | Q37: =SUBSTITUTE(O37,"No major surgery",0) -> 0 | R37: =PROPER(L37) -> No | S37: =PROPER(P37) -> Yes | T37: =SUBSTITUTE(S37,"?","No") -> Yes | U37: {=_xlfn.IFS(B37<18.5,"Underweight",B37<=24.9,"Normal weight",B37<=29.99,"Over weight",B37>=30,"Obesity")} -> Obesity | V37: {=_xlfn.IFS(C37<5.7,"Normal",C37<=6.49,"Prediabetes",C37>=6.5,"Diabetes")} -> Diabetes | W37: =PROPER(E37) -> No
A38: Id37 | B38: 40.565 | C38: 7.37 | D38: No | E38: No | F38: No | G38: No major surgery | H38: yes | I38: =CLEAN(A38) -> Id37 | J38: =CLEAN(B38) -> 40.565 | K38: =CLEAN(C38) -> 7.37 | L38: =CLEAN(D38) -> No | M38: =CLEAN(E38) -> No | N38: =CLEAN(F38) -> No | O38: =CLEAN(G38) -> No major surgery | P38: =CLEAN(H38) -> yes | Q38: =SUBSTITUTE(O38,"No major surgery",0) -> 0 | R38: =PROPER(L38) -> No | S38: =PROPER(P38) -> Yes | T38: =SUBSTITUTE(S38,"?","No") -> Yes | U38: {=_xlfn.IFS(B38<18.5,"Underweight",B38<=24.9,"Normal weight",B38<=29.99,"Over weight",B38>=30,"Obesity")} -> Obesity | V38: {=_xlfn.IFS(C38<5.7,"Normal",C38<=6.49,"Prediabetes",C38>=6.5,"Diabetes")} -> Diabetes | W38: =PROPER(E38) -> No
A39: Id38 | B39: 32.45 | C39: 11.91 | D39: No | E39: No | F39: No | G39: No major surgery | H39: yes | I39: =CLEAN(A39) -> Id38 | J39: =CLEAN(B39) -> 32.45 | K39: =CLEAN(C39) -> 11.91 | L39: =CLEAN(D39) -> No | M39: =CLEAN(E39) -> No | N39: =CLEAN(F39) -> No | O39: =CLEAN(G39) -> No major surgery | P39: =CLEAN(H39) -> yes | Q39: =SUBSTITUTE(O39,"No major surgery",0) -> 0 | R39: =PROPER(L39) -> No | S39: =PROPER(P39) -> Yes | T39: =SUBSTITUTE(S39,"?","No") -> Yes | U39: {=_xlfn.IFS(B39<18.5,"Underweight",B39<=24.9,"Normal weight",B39<=29.99,"Over weight",B39>=30,"Obesity")} -> Obesity | V39: {=_xlfn.IFS(C39<5.7,"Normal",C39<=6.49,"Prediabetes",C39>=6.5,"Diabetes")} -> Diabetes | W39: =PROPER(E39) -> No
A40: Id39 | B40: 34.96 | C40: 6.52 | D40: No | E40: No | F40: No | G40: No major surgery | H40: yes | I40: =CLEAN(A40) -> Id39 | J40: =CLEAN(B40) -> 34.96 | K40: =CLEAN(C40) -> 6.52 | L40: =CLEAN(D40) -> No | M40: =CLEAN(E40) -> No | N40: =CLEAN(F40) -> No | O40: =CLEAN(G40) -> No major surgery | P40: =CLEAN(H40) -> yes | Q40: =SUBSTITUTE(O40,"No major surgery",0) -> 0 | R40: =PROPER(L40) -> No | S40: =PROPER(P40) -> Yes | T40: =SUBSTITUTE(S40,"?","No") -> Yes | U40: {=_xlfn.IFS(B40<18.5,"Underweight",B40<=24.9,"Normal weight",B40<=29.99,"Over weight",B40>=30,"Obesity")} -> Obesity | V40: {=_xlfn.IFS(C40<5.7,"Normal",C40<=6.49,"Prediabetes",C40>=6.5,"Diabetes")} -> Diabetes | W40: =PROPER(E40) -> No
...

Sheet Hospitalisation Details
A1: Customer ID | B1: year | C1: month | D1: date | E1: Date of birth | F1: age | G1: children | H1: charges | I1: Hospital tier | J1: City tier | K1: State ID | L1: Hospital tier | M1: City tier | N1: State ID | W1: Month
A2: Id2335 | B2: 1992 | C2: Jul | D2: 9 | E2: =DATEVALUE(D2&"-"&C2&"-"&B2) -> 33794 | F2: =DATEDIF(E2,DATE(2023,6,8),"Y") -> 30 | G2: 0 | H2: 563.84 | I2: tier - 2 | J2: tier - 3 | K2: R1013 | L2: =SUBSTITUTE(I2,"?","tier - 2") -> tier - 2 | M2: =SUBSTITUTE(J2,"?","tier - 2") -> tier - 3 | N2: =SUBSTITUTE(K2,"?","Unknown") -> R1013
A3: Id2334 | B3: 1992 | C3: Nov | D3: 30 | E3: =DATEVALUE(D3&"-"&C3&"-"&B3) -> 33938 | F3: =DATEDIF(E3,DATE(2023,6,8),"Y") -> 30 | G3: 0 | H3: 570.62 | I3: tier - 2 | J3: tier - 1 | K3: R1013 | L3: =SUBSTITUTE(I3,"?","tier - 2") -> tier - 2 | M3: =SUBSTITUTE(J3,"?","tier - 2") -> tier - 1 | N3: =SUBSTITUTE(K3,"?","Unknown") -> R1013
A4: Id2333 | B4: 1993 | C4: Jun | D4: 30 | E4: =DATEVALUE(D4&"-"&C4&"-"&B4) -> 34150 | F4: =DATEDIF(E4,DATE(2023,6,8),"Y") -> 29 | G4: 0 | H4: 600 | I4: tier - 2 | J4: tier - 1 | K4: R1013 | L4: =SUBSTITUTE(I4,"?","tier - 2") -> tier - 2 | M4: =SUBSTITUTE(J4,"?","tier - 2") -> tier - 1 | N4: =SUBSTITUTE(K4,"?","Unknown") -> R1013
A5: Id2332 | B5: 1992 | C5: Sep | D5: 13 | E5: =DATEVALUE(D5&"-"&C5&"-"&B5) -> 33860 | F5: =DATEDIF(E5,DATE(2023,6,8),"Y") -> 30 | G5: 0 | H5: 604.54 | I5: tier - 3 | J5: tier - 3 | K5: R1013 | L5: =SUBSTITUTE(I5,"?","tier - 2") -> tier - 3 | M5: =SUBSTITUTE(J5,"?","tier - 2") -> tier - 3 | N5: =SUBSTITUTE(K5,"?","Unknown") -> R1013
A6: Id2331 | B6: 1998 | C6: Jul | D6: 27 | E6: =DATEVALUE(D6&"-"&C6&"-"&B6) -> 36003 | F6: =DATEDIF(E6,DATE(2023,6,8),"Y") -> 24 | G6: 0 | H6: 637.26 | I6: tier - 3 | J6: tier - 3 | K6: R1013 | L6: =SUBSTITUTE(I6,"?","tier - 2") -> tier - 3 | M6: =SUBSTITUTE(J6,"?","tier - 2") -> tier - 3 | N6: =SUBSTITUTE(K6,"?","Unknown") -> R1013
A7: Id2330 | B7: 2001 | C7: Nov | D7: 20 | E7: =DATEVALUE(D7&"-"&C7&"-"&B7) -> 37215 | F7: =DATEDIF(E7,DATE(2023,6,8),"Y") -> 21 | G7: 0 | H7: 646.14 | I7: tier - 3 | J7: tier - 3 | K7: R1012 | L7: =SUBSTITUTE(I7,"?","tier - 2") -> tier - 3 | M7: =SUBSTITUTE(J7,"?","tier - 2") -> tier - 3 | N7: =SUBSTITUTE(K7,"?","Unknown") -> R1012
A8: Id2329 | B8: 1993 | C8: Jun | D8: 1 | E8: =DATEVALUE(D8&"-"&C8&"-"&B8) -> 34121 | F8: =DATEDIF(E8,DATE(2023,6,8),"Y") -> 30 | G8: 0 | H8: 650 | I8: tier - 3 | J8: tier - 3 | K8: R1013 | L8: =SUBSTITUTE(I8,"?","tier - 2") -> tier - 3 | M8: =SUBSTITUTE(J8,"?","tier - 2") -> tier - 3 | N8: =SUBSTITUTE(K8,"?","Unknown") -> R1013
A9: Id2328 | B9: 1995 | C9: Jul | D9: 4 | E9: =DATEVALUE(D9&"-"&C9&"-"&B9) -> 34884 | F9: =DATEDIF(E9,DATE(2023,6,8),"Y") -> 27 | G9: 0 | H9: 650 | I9: tier - 3 | J9: tier - 3 | K9: R1013 | L9: =SUBSTITUTE(I9,"?","tier - 2") -> tier - 3 | M9: =SUBSTITUTE(J9,"?","tier - 2") -> tier - 3 | N9: =SUBSTITUTE(K9,"?","Unknown") -> R1013
A10: Id2327 | B10: 2002 | C10: Nov | D10: 29 | E10: =DATEVALUE(D10&"-"&C10&"-"&B10) -> 37589 | F10: =DATEDIF(E10,DATE(2023,6,8),"Y") -> 20 | G10: 0 | H10: 668 | I10: tier - 3 | J10: tier - 2 | K10: R1012 | L10: =SUBSTITUTE(I10,"?","tier - 2") -> tier - 3 | M10: =SUBSTITUTE(J10,"?","tier - 2") -> tier - 2 | N10: =SUBSTITUTE(K10,"?","Unknown") -> R1012
A11: Id2326 | B11: 1997 | C11: Nov | D11: 9 | E11: =DATEVALUE(D11&"-"&C11&"-"&B11) -> 35743 | F11: =DATEDIF(E11,DATE(2023,6,8),"Y") -> 25 | G11: 0 | H11: 670 | I11: tier - 3 | J11: tier - 3 | K11: R1013 | L11: =SUBSTITUTE(I11,"?","tier - 2") -> tier - 3 | M11: =SUBSTITUTE(J11,"?","tier - 2") -> tier - 3 | N11: =SUBSTITUTE(K11,"?","Unknown") -> R1013
A12: Id2325 | B12: 2001 | C12: Sep | D12: 12 | E12: =DATEVALUE(D12&"-"&C12&"-"&B12) -> 37146 | F12: =DATEDIF(E12,DATE(2023,6,8),"Y") -> 21 | G12: 0 | H12: 687.54 | I12: tier - 3 | J12: tier - 2 | K12: R1013 | L12: =SUBSTITUTE(I12,"?","tier - 2") -> tier - 3 | M12: =SUBSTITUTE(J12,"?","tier - 2") -> tier - 2 | N12: =SUBSTITUTE(K12,"?","Unknown") -> R1013
A13: Id2324 | B13: 1999 | C13: Dec | D13: 26 | E13: =DATEVALUE(D13&"-"&C13&"-"&B13) -> 36520 | F13: =DATEDIF(E13,DATE(2023,6,8),"Y") -> 23 | G13: 0 | H13: 700 | I13: ? | J13: tier - 3 | K13: R1013 | L13: =SUBSTITUTE(I13,"?","tier - 2") -> tier - 2 | M13: =SUBSTITUTE(J13,"?","tier - 2") -> tier - 3 | N13: =SUBSTITUTE(K13,"?","Unknown") -> R1013
... A2344: Id1 | B2344: 1968 | C2344: Oct | D2344: 12 | E2344: =DATEVALUE(D2344&"-"&C2344&"-"&B2344) -> 25123 | F2344: =DATEDIF(E2344,DATE(2023,6,8),"Y") -> 54 | G2344: 0 | H2344: 63770.43 | I2344: tier - 1 | J2344: tier - 3 | K2344: R1013 | L2344: =SUBSTITUTE(I2344,"?","tier - 2") -> tier - 1 | M2344: =SUBSTITUTE(J2344,"?","tier - 2") -> tier - 3 | N2344: =SUBSTITUTE(K2344,"?","Unknown") -> R1013
H2346: tier 1 | I2346: =COUNTIF(I1:I2344,"tier - 1") -> 309 | J2346: =COUNTIF(J1:J2344,"tier - 1") -> 734
B2347: =AVERAGE(B2:B2344) -> 1982.8417 | H2347: tier 2 | I2347: =COUNTIF(I1:I2344,"tier - 2") -> 1339 | J2347: =COUNTIF(J1:J2344,"tier - 2") -> 812 | S2347: countblank | U2347: =COUNTBLANK(U2:U2344) -> 2343 | V2347: =COUNTBLANK(V2:V2344) -> 2343 | W2347: =COUNTBLANK(W2:W2344) -> 2343 | X2347: =COUNTBLANK(X2:X2344) -> 2343 | Y2347: =COUNTBLANK(Y2:Y2344) -> 2343 | Z2347: =COUNTBLANK(Z2:Z2344) -> 2343 | AA2347: =COUNTBLANK(AA2:AA2344) -> 2343 | AB2347: =COUNTBLANK(AB2:AB2344) -> 2343 | AC2347: =COUNTBLANK(AC2:AC2344) -> 2343
H2348: tier 3 | I2348: =COUNTIF(I1:I2344,"tier - 3") -> 694 | J2348: =COUNTIF(J1:J2344,"tier - 3") -> 796
H2349: ? | I2349: =COUNTIF(I1:I2344,"?") -> 1 | J2349: =COUNTIF(J1:J2344,"?") -> 1
A2353: 6 | B2353: 2 | C2353: =COUNTIF(C15:C2342,"?") -> 0 | D2353: 0 | G2353: 0 | H2353: 0 | I2353: 1 | J2353: 1 | K2353: 2

Sheet Pie,Donut chart
A3: Customers | B3: Count of Cancer history
A4: Non-smokers | B4: 874
A5: Smokers | B5: 221
A11: History of transplants | B11: Total number of Major Surgeries | C11: Average of HBA1C
A12: Without transplant | B12: 669 | C12: 4.8536345
A13: With transplant | B13: 109 | C13: 4.8053535

Sheet Bar Chart
A2: Row Labels | B2: Average of charges
A3: tier - 1 | B3: 27784.908
A4: R1011 | B4: 30361.392
A5: R1012 | B5: 24115.368
A6: tier - 2 | B6: 13340.102
A7: R1011 | B7: 17412.474
A8: R1012 | B8: 9570.2497
A9: tier - 3 | B9: 9073.1154
A10: R1011 | B10: 8245.0893
A11: R1012 | B11: 9721.1358
A12: Grand Total | B12: 14508.149

Sheet Column Chart
A2: Row Labels | B2: Average of charges
A3: Normal weight | B3: 7897.0779
A4: Normal | B4: 7897.0779
A5: Obesity | B5: 15188.437
A6: Normal | B6: 15188.437
A7: Over weight | B7: 10323.941
A8: Normal | B8: 10323.941
A9: Underweight | B9: 6911.0056
A10: Normal | B10: 6911.0056
A11: Grand Total | B11: 12090.723

Sheet Line,Scatter Chart
A3: Age | B3: Sum of BMI | C3: Sum of HBA1C
A4: 26 | B4: 1032.035 | C4: 164.15
A5: 27 | B5: 1313.935 | C5: 204.2
A6: 28 | B6: 1112.24 | C6: 170.55
A7: 29 | B7: 1169.705 | C7: 179.06
A8: 30 | B8: 1223.775 | C8: 174.41
A9: 31 | B9: 959.59 | C9: 154.27
A10: 32 | B10: 1172.79 | C10: 168.56
A11: 33 | B11: 1132 | C11: 172.63
A12: 34 | B12: 1263.185 | C12: 199.44
A13: 35 | B13: 885.62 | C13: 139.63
A14: 36 | B14: 27.1 | C14: 5.08
A15: 37 | B15: 1197.655 | C15: 198.26
... A23: 50 | B23: 1194.535 | C23: 183.61
A24: Grand Total | B24: 20630.945 | C24: 3212.44

Sheet Dashboard Visualization
A1: HEALTHCARE ANALYSIS
